<?xml version="1.0" ?>
<!-- =================================================================================== -->
<!-- |    This document was autogenerated by xacro from /home/bolingy/RL_proj/spot_ws/src/tahoma_description/robots/tahoma.xacro | -->
<!-- |    EDITING THIS FILE BY HAND IS NOT RECOMMENDED                                 | -->
<!-- =================================================================================== -->
<robot name="tahoma">
  <material name="aluminum">
    <color rgba="0.5 0.5 0.5 1"/>
  </material>
  <material name="plastic">
    <color rgba="0.1 0.1 0.1 1"/>
  </material>
  <!-- this specific plug does not apply to L515 -->
  <material name="blue_aluminum">
    <!-- more accurate but less pretty :) -->
    <!--color rgba=".14 .24 .31 1"/>
      <color rgba=".26 .44 .545 1"/-->
    <color rgba=".23 .42 .64 1"/>
  </material>
  <link name="stand">
    <inertial>
      <mass value="10.0"/>
      <inertia ixx="0.0002835" ixy="0.0" ixz="0.0" iyy="0.0002835" iyz="0.0" izz="0.000324"/>
    </inertial>
    <visual>
      <origin rpy="0 0 0" xyz="0 0 0"/>
      <geometry>
        <mesh filename="package://tahoma_description/meshes/stand/stand_base.stl"/>
      </geometry>
      <material name="blue_aluminum"/>
    </visual>
    <collision>
      <!-- across -->
      <origin rpy="0 0 0" xyz=".4050 0 .0281"/>
      <geometry>
        <box size=".09 1.53 .045"/>
      </geometry>
    </collision>
    <collision>
      <!-- right -->
      <origin rpy="0 0 0" xyz="0 -.72 -.0225"/>
      <geometry>
        <box size=".9 .09 .0562"/>
      </geometry>
    </collision>
    <collision>
      <!-- left -->
      <origin rpy="0 0 0" xyz="0 .72 -.0225"/>
      <geometry>
        <box size=".9 .09 .0562"/>
      </geometry>
    </collision>
  </link>
  <link name="stand_upright">
    <inertial>
      <mass value="34"/>
      <inertia ixx="0.0002835" ixy="0.0" ixz="0.0" iyy="0.0002835" iyz="0.0" izz="0.000324"/>
    </inertial>
    <visual>
      <origin rpy="0 0 0" xyz="0 0 0"/>
      <geometry>
        <mesh filename="package://tahoma_description/meshes/stand/stand_upright.stl"/>
      </geometry>
      <material name="blue_aluminum"/>
    </visual>
    <collision>
      <!-- right upright -->
      <origin rpy="0 0 0" xyz="-.1709 0.6975 0"/>
      <geometry>
        <box size=".2298 .0450 1.89"/>
      </geometry>
    </collision>
    <collision>
      <!-- left upright -->
      <origin rpy="0 0 0" xyz="-.1709 -0.6975 0"/>
      <geometry>
        <box size=".2298 .0450 1.89"/>
      </geometry>
    </collision>
    <collision>
      <!-- top beam -->
      <origin rpy="0 0 0" xyz="-.1733 0 .9012"/>
      <geometry>
        <box size=".2370 1.44 .0960"/>
      </geometry>
    </collision>
  </link>
  <link name="stand_brace">
    <inertial>
      <mass value="5"/>
      <inertia ixx="0.0002835" ixy="0.0" ixz="0.0" iyy="0.0002835" iyz="0.0" izz="0.000324"/>
    </inertial>
    <visual>
      <origin rpy="0 0 0" xyz="0 0 0"/>
      <geometry>
        <mesh filename="package://tahoma_description/meshes/stand/stand_brace.stl"/>
      </geometry>
      <material name="blue_aluminum"/>
    </visual>
    <collision>
      <origin rpy="0 0 0" xyz="0 0 0"/>
      <geometry>
        <box size=".102 1.4390 .4934"/>
      </geometry>
    </collision>
  </link>
  <link name="camera_beam_lower">
    <inertial>
      <mass value="5"/>
      <inertia ixx="0.0002835" ixy="0.0" ixz="0.0" iyy="0.0002835" iyz="0.0" izz="0.000324"/>
    </inertial>
    <visual>
      <origin rpy="0 0 0" xyz="0 0 0"/>
      <geometry>
        <mesh filename="package://tahoma_description/meshes/stand/camera_beam.stl"/>
      </geometry>
      <material name="blue_aluminum"/>
    </visual>
    <collision>
      <origin rpy="0 0 .022" xyz="0 0 0"/>
      <geometry>
        <box size="0.045 1.25 0.045"/>
      </geometry>
    </collision>
  </link>
  <link name="cantilever">
    <inertial>
      <mass value="8"/>
      <inertia ixx="0.0002835" ixy="0.0" ixz="0.0" iyy="0.0002835" iyz="0.0" izz="0.000324"/>
    </inertial>
    <visual>
      <origin rpy="0 0 0" xyz="0 0 0"/>
      <geometry>
        <mesh filename="package://tahoma_description/meshes/stand/cantilever.stl"/>
      </geometry>
      <material name="blue_aluminum"/>
    </visual>
    <collision>
      <origin xyz="0 0 .0415"/>
      <geometry>
        <box size=".7260 .225 .09"/>
      </geometry>
    </collision>
  </link>
  <link name="control_box_mount">
    <inertial>
      <mass value="3"/>
      <inertia ixx="0.0002835" ixy="0.0" ixz="0.0" iyy="0.0002835" iyz="0.0" izz="0.000324"/>
    </inertial>
    <visual>
      <origin rpy="0 0 0" xyz="0 0 0"/>
      <geometry>
        <mesh filename="package://tahoma_description/meshes/stand/control_box_mount.stl"/>
      </geometry>
      <material name="blue_aluminum"/>
    </visual>
    <collision>
      <origin rpy="0 0 0" xyz="0 0 0"/>
      <geometry>
        <box size=".585 .0602 .1790"/>
      </geometry>
    </collision>
  </link>
  <link name="control_box">
    <inertial>
      <mass value="7"/>
      <inertia ixx="0.0002835" ixy="0.0" ixz="0.0" iyy="0.0002835" iyz="0.0" izz="0.000324"/>
    </inertial>
    <visual>
      <origin rpy="0 0 0" xyz="0 0 0"/>
      <geometry>
        <mesh filename="package://tahoma_description/meshes/stand/control_box.stl"/>
      </geometry>
      <material name="aluminum"/>
    </visual>
    <collision>
      <origin rpy="0 0 0" xyz="0 0 0"/>
      <geometry>
        <box size=".46 .25 .44"/>
      </geometry>
    </collision>
  </link>
  <link name="robot_plate">
    <inertial>
      <mass value=".5"/>
      <inertia ixx="0.0002835" ixy="0.0" ixz="0.0" iyy="0.0002835" iyz="0.0" izz="0.000324"/>
    </inertial>
    <visual>
      <origin rpy="0 0 0" xyz="0 0 0"/>
      <geometry>
        <mesh filename="package://tahoma_description/meshes/stand/robot_plate.stl"/>
      </geometry>
      <material name="blue_aluminum"/>
    </visual>
    <collision>
      <origin rpy="0 0 0" xyz="0 0 0"/>
      <geometry>
        <box size=".225 .225 .0225"/>
      </geometry>
    </collision>
  </link>
  <!--material name="guard">
      <color rgba="1 .97 .89 1"/>
    </material-->
  <link name="front_right_caster">
    <inertial>
      <!-- Roughly caster, plate and bolts -->
      <mass value="1.0"/>
      <inertia ixx="0.0002835" ixy="0.0" ixz="0.0" iyy="0.0002835" iyz="0.0" izz="0.0002835"/>
    </inertial>
    <visual>
      <origin rpy="1.56 0 0" xyz="0 0 0"/>
      <geometry>
        <mesh filename="package://tahoma_description/meshes/stand/caster.stl"/>
      </geometry>
      <material name="wheel">
        <color rgba=".2 .2 .2 1"/>
      </material>
    </visual>
    <collision>
      <origin rpy="1.56 0 0" xyz="0 0 0"/>
      <geometry>
        <box size="0.09 0.1040 0.1225"/>
      </geometry>
    </collision>
  </link>
  <!--material name="guard">
      <color rgba="1 .97 .89 1"/>
    </material-->
  <link name="front_left_caster">
    <inertial>
      <!-- Roughly caster, plate and bolts -->
      <mass value="1.0"/>
      <inertia ixx="0.0002835" ixy="0.0" ixz="0.0" iyy="0.0002835" iyz="0.0" izz="0.0002835"/>
    </inertial>
    <visual>
      <origin rpy="1.56 0 0" xyz="0 0 0"/>
      <geometry>
        <mesh filename="package://tahoma_description/meshes/stand/caster.stl"/>
      </geometry>
      <material name="wheel">
        <color rgba=".2 .2 .2 1"/>
      </material>
    </visual>
    <collision>
      <origin rpy="1.56 0 0" xyz="0 0 0"/>
      <geometry>
        <box size="0.09 0.1040 0.1225"/>
      </geometry>
    </collision>
  </link>
  <!--material name="guard">
      <color rgba="1 .97 .89 1"/>
    </material-->
  <link name="back_left_caster">
    <inertial>
      <!-- Roughly caster, plate and bolts -->
      <mass value="1.0"/>
      <inertia ixx="0.0002835" ixy="0.0" ixz="0.0" iyy="0.0002835" iyz="0.0" izz="0.0002835"/>
    </inertial>
    <visual>
      <origin rpy="1.56 0 0" xyz="0 0 0"/>
      <geometry>
        <mesh filename="package://tahoma_description/meshes/stand/caster.stl"/>
      </geometry>
      <material name="wheel">
        <color rgba=".2 .2 .2 1"/>
      </material>
    </visual>
    <collision>
      <origin rpy="1.56 0 0" xyz="0 0 0"/>
      <geometry>
        <box size="0.09 0.1040 0.1225"/>
      </geometry>
    </collision>
  </link>
  <!--material name="guard">
      <color rgba="1 .97 .89 1"/>
    </material-->
  <link name="back_right_caster">
    <inertial>
      <!-- Roughly caster, plate and bolts -->
      <mass value="1.0"/>
      <inertia ixx="0.0002835" ixy="0.0" ixz="0.0" iyy="0.0002835" iyz="0.0" izz="0.0002835"/>
    </inertial>
    <visual>
      <origin rpy="1.56 0 0" xyz="0 0 0"/>
      <geometry>
        <mesh filename="package://tahoma_description/meshes/stand/caster.stl"/>
      </geometry>
      <material name="wheel">
        <color rgba=".2 .2 .2 1"/>
      </material>
    </visual>
    <collision>
      <origin rpy="1.56 0 0" xyz="0 0 0"/>
      <geometry>
        <box size="0.09 0.1040 0.1225"/>
      </geometry>
    </collision>
  </link>
  <link name="left_light_panel">
    <inertial>
      <mass value="1.0"/>
      <inertia ixx="0.0002835" ixy="0.0" ixz="0.0" iyy="0.0002835" iyz="0.0" izz="0.0002835"/>
    </inertial>
    <visual>
      <origin rpy="0 0 0" xyz="0 0 0"/>
      <geometry>
        <box size="1.21 .602 .01"/>
      </geometry>
      <material name="gray">
        <color rgba=".3 .3 .3 1"/>
      </material>
    </visual>
    <collision>
      <origin rpy="0 0 0" xyz="0 0 0"/>
      <geometry>
        <box size="1.21 .602 .01"/>
      </geometry>
    </collision>
  </link>
  <link name="left_light_panel_emitter">
    <visual>
      <origin rpy="0 0 0" xyz="0 0 .005"/>
      <geometry>
        <box size="1.17 .562 .00251"/>
      </geometry>
      <material name="white">
        <color rgba=".9 .9 .9 1"/>
      </material>
    </visual>
    <collision>
      <origin rpy="0 0 0" xyz="0 0 0"/>
      <geometry>
        <box size="1.17 .562 .00251"/>
      </geometry>
    </collision>
  </link>
  <joint name="left_light_panel_left_light_panel_emitter_joint" type="fixed">
    <parent link="left_light_panel"/>
    <child link="left_light_panel_emitter"/>
  </joint>
  <link name="right_light_panel">
    <inertial>
      <mass value="1.0"/>
      <inertia ixx="0.0002835" ixy="0.0" ixz="0.0" iyy="0.0002835" iyz="0.0" izz="0.0002835"/>
    </inertial>
    <visual>
      <origin rpy="0 0 0" xyz="0 0 0"/>
      <geometry>
        <box size="1.21 .602 .01"/>
      </geometry>
      <material name="gray">
        <color rgba=".3 .3 .3 1"/>
      </material>
    </visual>
    <collision>
      <origin rpy="0 0 0" xyz="0 0 0"/>
      <geometry>
        <box size="1.21 .602 .01"/>
      </geometry>
    </collision>
  </link>
  <link name="right_light_panel_emitter">
    <visual>
      <origin rpy="0 0 0" xyz="0 0 .005"/>
      <geometry>
        <box size="1.17 .562 .00251"/>
      </geometry>
      <material name="white">
        <color rgba=".9 .9 .9 1"/>
      </material>
    </visual>
    <collision>
      <origin rpy="0 0 0" xyz="0 0 0"/>
      <geometry>
        <box size="1.17 .562 .00251"/>
      </geometry>
    </collision>
  </link>
  <joint name="right_light_panel_right_light_panel_emitter_joint" type="fixed">
    <parent link="right_light_panel"/>
    <child link="right_light_panel_emitter"/>
  </joint>
  <joint name="stand_stand_upright_joint" type="fixed">
    <parent link="stand"/>
    <child link="stand_upright"/>
    <origin rpy="0 0 0" xyz="-.12 0 .95"/>
  </joint>
  <joint name="stand_upright_stand_brace_joint" type="fixed">
    <parent link="stand_upright"/>
    <child link="stand_brace"/>
    <origin rpy="0 0 0" xyz="-.24 0 -.59"/>
  </joint>
  <joint name="stand_upright_camera_beam_lower_joint" type="fixed">
    <parent link="stand_upright"/>
    <child link="camera_beam_lower"/>
    <origin rpy="0 0 0" xyz="-.228 0 .35"/>
  </joint>
  <joint name="stand_upright_robot_control_box_mount_joint" type="fixed">
    <parent link="stand_upright"/>
    <child link="control_box_mount"/>
    <origin rpy="0 0 0" xyz="-.1725 .7475 .21"/>
  </joint>
  <joint name="control_box_mount_control_box_joint" type="fixed">
    <parent link="control_box_mount"/>
    <child link="control_box"/>
    <origin rpy="0.05 0 3.141592653589793" xyz="-.003 .1375 -0.13"/>
  </joint>
  <joint name="stand_cantilever_joint" type="fixed">
    <parent link="stand_upright"/>
    <child link="cantilever"/>
    <origin rpy="0 0 0" xyz=".0775 0  0.9442"/>
  </joint>
  <joint name="cantilever_robot_plate_joint" type="fixed">
    <parent link="cantilever"/>
    <child link="robot_plate"/>
    <origin rpy="0 0 0" xyz="0.2505 0 -.015"/>
  </joint>
  <joint name="stand_front_right_caster_joint" type="fixed">
    <parent link="stand"/>
    <child link="front_right_caster"/>
    <origin rpy="0 0 0" xyz=".405 -.7375 -0.1"/>
  </joint>
  <joint name="stand_front_left_caster_joint" type="fixed">
    <parent link="stand"/>
    <child link="front_left_caster"/>
    <origin rpy="0 0 0" xyz=".405 .7025 -0.1"/>
  </joint>
  <joint name="stand_back_right_caster_joint" type="fixed">
    <parent link="stand"/>
    <child link="back_right_caster"/>
    <origin rpy="0 0 0" xyz="-.405 -.7375 -0.1"/>
  </joint>
  <joint name="stand_back_left_caster_joint" type="fixed">
    <parent link="stand"/>
    <child link="back_left_caster"/>
    <origin rpy="0 0 0" xyz="-.405 .7025 -0.1"/>
  </joint>
  <joint name="stand_left_light_panel_joint" type="fixed">
    <parent link="stand_upright"/>
    <child link="left_light_panel"/>
    <origin rpy="0 1.5707963267948966 0" xyz="-.2625 .35 .25"/>
  </joint>
  <joint name="stand_left_right_panel_joint" type="fixed">
    <parent link="stand_upright"/>
    <child link="right_light_panel"/>
    <origin rpy="0 1.5707963267948966 0" xyz="-.2625 -.35 .25"/>
  </joint>
  <!--
    Base UR robot series xacro macro.

    NOTE: this is NOT a URDF. It cannot directly be loaded by consumers
    expecting a flattened '.urdf' file. See the top-level '.xacro' for that
    (but note: that .xacro must still be processed by the xacro command).

    For use in '.launch' files: use one of the 'load_urX.launch' convenience
    launch files.

    This file models the base kinematic chain of a UR robot, which then gets
    parameterised by various configuration files to convert it into a UR3(e),
    UR5(e), UR10(e) or UR16e.

    NOTE: the default kinematic parameters (ie: link lengths, frame locations,
    offets, etc) do not correspond to any particular robot. They are defaults
    only. There WILL be non-zero offsets between the Forward Kinematics results
    in TF (ie: robot_state_publisher) and the values reported by the Teach
    Pendant.

    For accurate (and robot-specific) transforms, the 'kinematics_parameters_file'
    parameter MUST point to a .yaml file containing the appropriate values for
    the targetted robot.

    If using the UniversalRobots/Universal_Robots_ROS_Driver, follow the steps
    described in the readme of that repository to extract the kinematic
    calibration from the controller and generate the required .yaml file.

    Main author of the migration to yaml configs: Ludovic Delval.

    Contributors to previous versions (in no particular order):

     - Felix Messmer
     - Kelsey Hawkins
     - Wim Meeussen
     - Shaun Edwards
     - Nadia Hammoudeh Garcia
     - Dave Hershberger
     - G. vd. Hoorn
     - Philip Long
     - Dave Coleman
     - Miguel Prada
     - Mathias Luedtke
     - Marcel Schnirring
     - Felix von Drigalski
     - Felix Exner
     - Jimmy Da Silva
     - Ajit Krisshna N L
     - Muhammad Asif Rana
  -->
  <!--
    NOTE: the macro defined in this file is NOT part of the public API of this
          package. Users CANNOT rely on this file being available, or stored in
          this location. Nor can they rely on the existence of the macro.
  -->
  <transmission name="arm_shoulder_pan_trans">
    <type>transmission_interface/SimpleTransmission</type>
    <joint name="arm_shoulder_pan_joint">
      <hardwareInterface>hardware_interface/PositionJointInterface</hardwareInterface>
    </joint>
    <actuator name="arm_shoulder_pan_motor">
      <mechanicalReduction>1</mechanicalReduction>
    </actuator>
  </transmission>
  <transmission name="arm_shoulder_lift_trans">
    <type>transmission_interface/SimpleTransmission</type>
    <joint name="arm_shoulder_lift_joint">
      <hardwareInterface>hardware_interface/PositionJointInterface</hardwareInterface>
    </joint>
    <actuator name="arm_shoulder_lift_motor">
      <mechanicalReduction>1</mechanicalReduction>
    </actuator>
  </transmission>
  <transmission name="arm_elbow_trans">
    <type>transmission_interface/SimpleTransmission</type>
    <joint name="arm_elbow_joint">
      <hardwareInterface>hardware_interface/PositionJointInterface</hardwareInterface>
    </joint>
    <actuator name="arm_elbow_motor">
      <mechanicalReduction>1</mechanicalReduction>
    </actuator>
  </transmission>
  <transmission name="arm_wrist_1_trans">
    <type>transmission_interface/SimpleTransmission</type>
    <joint name="arm_wrist_1_joint">
      <hardwareInterface>hardware_interface/PositionJointInterface</hardwareInterface>
    </joint>
    <actuator name="arm_wrist_1_motor">
      <mechanicalReduction>1</mechanicalReduction>
    </actuator>
  </transmission>
  <transmission name="arm_wrist_2_trans">
    <type>transmission_interface/SimpleTransmission</type>
    <joint name="arm_wrist_2_joint">
      <hardwareInterface>hardware_interface/PositionJointInterface</hardwareInterface>
    </joint>
    <actuator name="arm_wrist_2_motor">
      <mechanicalReduction>1</mechanicalReduction>
    </actuator>
  </transmission>
  <transmission name="arm_wrist_3_trans">
    <type>transmission_interface/SimpleTransmission</type>
    <joint name="arm_wrist_3_joint">
      <hardwareInterface>hardware_interface/PositionJointInterface</hardwareInterface>
    </joint>
    <actuator name="arm_wrist_3_motor">
      <mechanicalReduction>1</mechanicalReduction>
    </actuator>
  </transmission>
  <!-- links: main serial chain -->
  <link name="arm_base_link"/>
  <link name="arm_base_link_inertia">
    <visual>
      <origin rpy="0 0 3.141592653589793" xyz="0 0 0"/>
      <geometry>
        <mesh filename="package://ur_description/meshes/ur10e/visual/base.dae"/>
      </geometry>
      <material name="LightGrey">
        <color rgba="0.7 0.7 0.7 1.0"/>
      </material>
    </visual>
    <collision>
      <origin rpy="0 0 3.141592653589793" xyz="0 0 0"/>
      <geometry>
        <mesh filename="package://ur_description/meshes/ur10e/collision/base.stl"/>
      </geometry>
    </collision>
    <inertial>
      <mass value="4.0"/>
      <origin rpy="0 0 0" xyz="0 0 0"/>
      <inertia ixx="0.0061063308908" ixy="0.0" ixz="0.0" iyy="0.0061063308908" iyz="0.0" izz="0.01125"/>
    </inertial>
  </link>
  <link name="arm_shoulder_link">
    <visual>
      <origin rpy="0 0 3.141592653589793" xyz="0 0 0"/>
      <geometry>
        <mesh filename="package://ur_description/meshes/ur10e/visual/shoulder.dae"/>
      </geometry>
      <material name="LightGrey">
        <color rgba="0.7 0.7 0.7 1.0"/>
      </material>
    </visual>
    <collision>
      <origin rpy="0 0 3.141592653589793" xyz="0 0 0"/>
      <geometry>
        <mesh filename="package://ur_description/meshes/ur10e/collision/shoulder.stl"/>
      </geometry>
    </collision>
    <inertial>
      <mass value="7.369"/>
      <origin rpy="0 0 0" xyz="0 0 0"/>
      <inertia ixx="0.029819260655624295" ixy="0.0" ixz="0.0" iyy="0.029819260655624295" iyz="0.0" izz="0.020725312499999995"/>
    </inertial>
  </link>
  <link name="arm_upper_arm_link">
    <visual>
      <origin rpy="1.5707963267948966 0 -1.5707963267948966" xyz="0 0 0.176"/>
      <geometry>
        <mesh filename="package://ur_description/meshes/ur16e/visual/upperarm.dae"/>
      </geometry>
      <material name="LightGrey">
        <color rgba="0.7 0.7 0.7 1.0"/>
      </material>
    </visual>
    <collision>
      <origin rpy="1.5707963267948966 0 -1.5707963267948966" xyz="0 0 0.176"/>
      <geometry>
        <mesh filename="package://ur_description/meshes/ur16e/collision/upperarm.stl"/>
      </geometry>
    </collision>
    <inertial>
      <mass value="10.45"/>
      <origin rpy="0 1.5707963267948966 0" xyz="-0.2392 0.0 0.175"/>
      <inertia ixx="0.21399985623335657" ixy="0.0" ixz="0.0" iyy="0.21399985623335657" iyz="0.0" izz="0.029390624999999997"/>
    </inertial>
  </link>
  <link name="arm_forearm_link">
    <visual>
      <origin rpy="1.5707963267948966 0 -1.5707963267948966" xyz="0 0 0.04"/>
      <geometry>
        <mesh filename="package://ur_description/meshes/ur16e/visual/forearm.dae"/>
      </geometry>
      <material name="LightGrey">
        <color rgba="0.7 0.7 0.7 1.0"/>
      </material>
    </visual>
    <collision>
      <origin rpy="1.5707963267948966 0 -1.5707963267948966" xyz="0 0 0.04"/>
      <geometry>
        <mesh filename="package://ur_description/meshes/ur16e/collision/forearm.stl"/>
      </geometry>
    </collision>
    <inertial>
      <mass value="4.321"/>
      <origin rpy="0 1.5707963267948966 0" xyz="-0.18 0.0 0.04"/>
      <inertia ixx="0.052743185152717496" ixy="0.0" ixz="0.0" iyy="0.052743185152717496" iyz="0.0" izz="0.012152812499999997"/>
    </inertial>
  </link>
  <link name="arm_wrist_1_link">
    <visual>
      <!-- TODO: Move this to a parameter -->
      <origin rpy="1.5707963267948966 0 0" xyz="0 0 -0.135"/>
      <geometry>
        <mesh filename="package://ur_description/meshes/ur10e/visual/wrist1.dae"/>
      </geometry>
      <material name="LightGrey">
        <color rgba="0.7 0.7 0.7 1.0"/>
      </material>
    </visual>
    <collision>
      <origin rpy="1.5707963267948966 0 0" xyz="0 0 -0.135"/>
      <geometry>
        <mesh filename="package://ur_description/meshes/ur10e/collision/wrist1.stl"/>
      </geometry>
    </collision>
    <inertial>
      <mass value="2.18"/>
      <origin rpy="0 0 0" xyz="0 0 0"/>
      <inertia ixx="0.0056816227273499996" ixy="0.0" ixz="0.0" iyy="0.0056816227273499996" iyz="0.0" izz="0.00613125"/>
    </inertial>
  </link>
  <link name="arm_wrist_2_link">
    <visual>
      <origin rpy="0 0 0" xyz="0 0 -0.12"/>
      <geometry>
        <mesh filename="package://ur_description/meshes/ur10e/visual/wrist2.dae"/>
      </geometry>
      <material name="LightGrey">
        <color rgba="0.7 0.7 0.7 1.0"/>
      </material>
    </visual>
    <collision>
      <origin rpy="0 0 0" xyz="0 0 -0.12"/>
      <geometry>
        <mesh filename="package://ur_description/meshes/ur10e/collision/wrist2.stl"/>
      </geometry>
    </collision>
    <inertial>
      <mass value="2.033"/>
      <origin rpy="0 0 0" xyz="0 0 0"/>
      <inertia ixx="0.0052985041305975" ixy="0.0" ixz="0.0" iyy="0.0052985041305975" iyz="0.0" izz="0.0057178125"/>
    </inertial>
  </link>
  <link name="arm_wrist_3_link">
    <visual>
      <origin rpy="1.5707963267948966 0 0" xyz="0 0 -0.1168"/>
      <geometry>
        <mesh filename="package://ur_description/meshes/ur10e/visual/wrist3.dae"/>
      </geometry>
      <material name="LightGrey">
        <color rgba="0.7 0.7 0.7 1.0"/>
      </material>
    </visual>
    <collision>
      <origin rpy="1.5707963267948966 0 0" xyz="0 0 -0.1168"/>
      <geometry>
        <mesh filename="package://ur_description/meshes/ur10e/collision/wrist3.stl"/>
      </geometry>
    </collision>
    <inertial>
      <mass value="0.907"/>
      <origin rpy="0 0 0" xyz="0.0 0.0 -0.025"/>
      <inertia ixx="0.0006481268240825001" ixy="0.0" ixz="0.0" iyy="0.0006481268240825001" iyz="0.0" izz="0.0009183374999999999"/>
    </inertial>
  </link>
  <!-- joints: main serial chain -->
  <joint name="arm_base_link-base_link_inertia" type="fixed">
    <parent link="arm_base_link"/>
    <child link="arm_base_link_inertia"/>
    <!-- 'base_link' is REP-103 aligned (so X+ forward), while the internal
           frames of the robot/controller have X+ pointing backwards.
           Use the joint between 'base_link' and 'base_link_inertia' (a dummy
           link/frame) to introduce the necessary rotation over Z (of pi rad).
      -->
    <origin rpy="0 0 3.141592653589793" xyz="0 0 0"/>
  </joint>
  <joint name="arm_shoulder_pan_joint" type="revolute">
    <parent link="arm_base_link_inertia"/>
    <child link="arm_shoulder_link"/>
    <origin rpy="0 0 0" xyz="0 0 0.1807"/>
    <axis xyz="0 0 1"/>
    <limit effort="330.0" lower="-6.283185307179586" upper="6.283185307179586" velocity="2.0943951023931953"/>
    <dynamics damping="0" friction="0"/>
  </joint>
  <joint name="arm_shoulder_lift_joint" type="revolute">
    <parent link="arm_shoulder_link"/>
    <child link="arm_upper_arm_link"/>
    <origin rpy="1.570796327 0 0" xyz="0 0 0"/>
    <axis xyz="0 0 1"/>
    <limit effort="330.0" lower="-6.283185307179586" upper="6.283185307179586" velocity="2.0943951023931953"/>
    <dynamics damping="0" friction="0"/>
  </joint>
  <joint name="arm_elbow_joint" type="revolute">
    <parent link="arm_upper_arm_link"/>
    <child link="arm_forearm_link"/>
    <origin rpy="0 0 0" xyz="-0.4784 0 0"/>
    <axis xyz="0 0 1"/>
    <limit effort="150.0" lower="-3.141592653589793" upper="3.141592653589793" velocity="3.141592653589793"/>
    <dynamics damping="0" friction="0"/>
  </joint>
  <joint name="arm_wrist_1_joint" type="revolute">
    <parent link="arm_forearm_link"/>
    <child link="arm_wrist_1_link"/>
    <origin rpy="0 0 0" xyz="-0.36 0 0.17415"/>
    <axis xyz="0 0 1"/>
    <limit effort="56.0" lower="-6.283185307179586" upper="6.283185307179586" velocity="3.141592653589793"/>
    <dynamics damping="0" friction="0"/>
  </joint>
  <joint name="arm_wrist_2_joint" type="revolute">
    <parent link="arm_wrist_1_link"/>
    <child link="arm_wrist_2_link"/>
    <origin rpy="1.570796327 0 0" xyz="0 -0.11985 -2.458164590756244e-11"/>
    <axis xyz="0 0 1"/>
    <limit effort="56.0" lower="-6.283185307179586" upper="6.283185307179586" velocity="3.141592653589793"/>
    <dynamics damping="0" friction="0"/>
  </joint>
  <joint name="arm_wrist_3_joint" type="revolute">
    <parent link="arm_wrist_2_link"/>
    <child link="arm_wrist_3_link"/>
    <origin rpy="1.570796326589793 3.141592653589793 3.141592653589793" xyz="0 0.11655 -2.390480459346185e-11"/>
    <axis xyz="0 0 1"/>
    <limit effort="56.0" lower="-6.283185307179586" upper="6.283185307179586" velocity="3.141592653589793"/>
    <dynamics damping="0" friction="0"/>
  </joint>
  <!-- ROS-Industrial 'base' frame: base_link to UR 'Base' Coordinates transform -->
  <link name="arm_base"/>
  <joint name="arm_base_link-base_fixed_joint" type="fixed">
    <!-- Note the rotation over Z of pi radians: as base_link is REP-103
           aligned (ie: has X+ forward, Y+ left and Z+ up), this is needed
           to correctly align 'base' with the 'Base' coordinate system of
           the UR controller.
      -->
    <origin rpy="0 0 3.141592653589793" xyz="0 0 0"/>
    <parent link="arm_base_link"/>
    <child link="arm_base"/>
  </joint>
  <!-- ROS-Industrial 'flange' frame: attachment point for EEF models -->
  <link name="arm_flange"/>
  <joint name="arm_wrist_3-flange" type="fixed">
    <parent link="arm_wrist_3_link"/>
    <child link="arm_flange"/>
    <origin rpy="0 -1.5707963267948966 -1.5707963267948966" xyz="0 0 0"/>
  </joint>
  <!-- ROS-Industrial 'tool0' frame: all-zeros tool frame -->
  <link name="arm_tool0"/>
  <joint name="arm_flange-tool0" type="fixed">
    <!-- default toolframe: X+ left, Y+ up, Z+ front -->
    <origin rpy="1.5707963267948966 0 1.5707963267948966" xyz="0 0 0"/>
    <parent link="arm_flange"/>
    <child link="arm_tool0"/>
  </joint>
  <transmission name="gripper_finger_joint_trans">
    <type>transmission_interface/SimpleTransmission</type>
    <joint name="gripper_finger_joint">
      <hardwareInterface>hardware_interface/EffortJointInterface</hardwareInterface>
    </joint>
    <actuator name="gripper_finger_joint_motor">
      <mechanicalReduction>1</mechanicalReduction>
    </actuator>
  </transmission>
  <!-- base link -->
  <link name="gripper_base_link"/>
  <joint name="gripper_base_link-gripper_robotiq_arg2f_base_link" type="fixed">
    <parent link="gripper_base_link"/>
    <child link="gripper_robotiq_arg2f_base_link"/>
  </joint>
  <link name="gripper_robotiq_arg2f_base_link">
    <inertial>
      <origin rpy="0 0 0" xyz="8.625E-08 -4.6583E-06 0.03145"/>
      <mass value="0.22652"/>
      <inertia ixx="0.00020005" ixy="-4.2442E-10" ixz="-2.9069E-10" iyy="0.00017832" iyz="-3.4402E-08" izz="0.00013478"/>
    </inertial>
    <visual>
      <origin rpy="0 0 0" xyz="0 0 0"/>
      <geometry>
        <mesh filename="package://robotiq_2f_85_gripper_visualization/meshes/visual/robotiq_arg2f_base_link.stl"/>
      </geometry>
      <material name="">
        <color rgba="0.1 0.1 0.1 1"/>
      </material>
    </visual>
    <collision>
      <origin rpy="0 0 0" xyz="0 0 0"/>
      <geometry>
        <mesh filename="package://robotiq_2f_85_gripper_visualization/meshes/collision/robotiq_arg2f_base_link.stl"/>
      </geometry>
    </collision>
  </link>
  <link name="gripper_left_outer_knuckle">
    <inertial>
      <origin rpy="0 0 0" xyz="-0.000200000000003065 0.0199435877845359 0.0292245259211331"/>
      <mass value="0.00853198276973456"/>
      <inertia ixx="2.89328108496468E-06" ixy="-1.57935047237397E-19" ixz="-1.93980378593255E-19" iyy="1.86719750325683E-06" iyz="-1.21858577871576E-06" izz="1.21905238907251E-06"/>
    </inertial>
    <visual>
      <origin rpy="0 0 0" xyz="0 0 0"/>
      <geometry>
        <mesh filename="package://robotiq_2f_85_gripper_visualization/meshes/visual/robotiq_arg2f_85_outer_knuckle.dae" scale="0.001 0.001 0.001"/>
      </geometry>
      <material name="">
        <color rgba="0.792156862745098 0.819607843137255 0.933333333333333 1"/>
      </material>
    </visual>
    <collision>
      <origin rpy="0 0 0" xyz="0 0 0"/>
      <geometry>
        <mesh filename="package://robotiq_2f_85_gripper_visualization/meshes/collision/robotiq_arg2f_85_outer_knuckle.dae" scale="0.001 0.001 0.001"/>
      </geometry>
    </collision>
  </link>
  <link name="gripper_left_outer_finger">
    <inertial>
      <origin rpy="0 0 0" xyz="0.00030115855001899 0.0373907951953854 -0.0208027427000385"/>
      <mass value="0.022614240507152"/>
      <inertia ixx="1.52518312458174E-05" ixy="9.76583423954399E-10" ixz="-5.43838577022588E-10" iyy="6.17694243867776E-06" iyz="6.78636130740228E-06" izz="1.16494917907219E-05"/>
    </inertial>
    <visual>
      <origin rpy="0 0 0" xyz="0 0 0"/>
      <geometry>
        <mesh filename="package://robotiq_2f_85_gripper_visualization/meshes/visual/robotiq_arg2f_85_outer_finger.dae" scale="0.001 0.001 0.001"/>
      </geometry>
      <material name="">
        <color rgba="0.1 0.1 0.1 1"/>
      </material>
    </visual>
    <collision>
      <origin rpy="0 0 0" xyz="0 0 0"/>
      <geometry>
        <mesh filename="package://robotiq_2f_85_gripper_visualization/meshes/collision/robotiq_arg2f_85_outer_finger.dae" scale="0.001 0.001 0.001"/>
      </geometry>
    </collision>
  </link>
  <link name="gripper_left_inner_finger">
    <inertial>
      <origin rpy="0 0 0" xyz="0.000299999999999317 0.0160078233491243 -0.0136945669206257"/>
      <mass value="0.0104003125914103"/>
      <inertia ixx="2.71909453810972E-06" ixy="1.35402465472579E-21" ixz="-7.1817349065269E-22" iyy="7.69100314106116E-07" iyz="6.74715432769696E-07" izz="2.30315190420171E-06"/>
    </inertial>
    <visual>
      <origin rpy="0 0 0" xyz="0 0 0"/>
      <geometry>
        <mesh filename="package://robotiq_2f_85_gripper_visualization/meshes/visual/robotiq_arg2f_85_inner_finger.dae" scale="0.001 0.001 0.001"/>
      </geometry>
      <material name="">
        <color rgba="0.1 0.1 0.1 1"/>
      </material>
    </visual>
    <collision>
      <origin rpy="0 0 0" xyz="0 0 0"/>
      <geometry>
        <mesh filename="package://robotiq_2f_85_gripper_visualization/meshes/collision/robotiq_arg2f_85_inner_finger.dae" scale="0.001 0.001 0.001"/>
      </geometry>
    </collision>
  </link>
  <link name="gripper_left_inner_finger_pad">
    <visual>
      <origin rpy="0 0 0" xyz="0 0 0"/>
      <geometry>
        <box size="0.022 0.00635 0.0375"/>
      </geometry>
      <material name="">
        <color rgba="0.9 0.9 0.9 1"/>
      </material>
    </visual>
    <collision>
      <origin rpy="0 0 0" xyz="0 0 0"/>
      <geometry>
        <box size="0.022 0.00635 0.0375"/>
      </geometry>
      <material name="">
        <color rgba="0.9 0.0 0.0 1"/>
      </material>
    </collision>
  </link>
  <link name="gripper_left_inner_knuckle">
    <inertial>
      <origin rpy="0 0 0" xyz="0.000123011831763771 0.0507850843201817 0.00103968640075166"/>
      <mass value="0.0271177346495152"/>
      <inertia ixx="2.61910379223783E-05" ixy="-2.43616858946494E-07" ixz="-6.37789906117123E-09" iyy="2.8270243746167E-06" iyz="-5.37200748039765E-07" izz="2.83695868220296E-05"/>
    </inertial>
    <visual>
      <origin rpy="0 0 0" xyz="0 0 0"/>
      <geometry>
        <mesh filename="package://robotiq_2f_85_gripper_visualization/meshes/visual/robotiq_arg2f_85_inner_knuckle.dae" scale="0.001 0.001 0.001"/>
      </geometry>
      <material name="">
        <color rgba="0.1 0.1 0.1 1"/>
      </material>
    </visual>
    <collision>
      <origin rpy="0 0 0" xyz="0 0 0"/>
      <geometry>
        <mesh filename="package://robotiq_2f_85_gripper_visualization/meshes/collision/robotiq_arg2f_85_inner_knuckle.dae" scale="0.001 0.001 0.001"/>
      </geometry>
    </collision>
  </link>
  <joint name="gripper_left_outer_finger_joint" type="fixed">
    <origin rpy="0 0 0" xyz="0 0.0315 -0.0041"/>
    <parent link="gripper_left_outer_knuckle"/>
    <child link="gripper_left_outer_finger"/>
    <axis xyz="1 0 0"/>
  </joint>
  <joint name="gripper_left_inner_knuckle_joint" type="revolute">
    <!-- <origin xyz="0 ${reflect * -0.0127} 0.06142" rpy="${pi / 2 + .725} 0 ${(reflect - 1) * pi / 2}" /> -->
    <origin rpy="0 0 3.141592653589793" xyz="0 -0.0127 0.06142"/>
    <parent link="gripper_robotiq_arg2f_base_link"/>
    <child link="gripper_left_inner_knuckle"/>
    <axis xyz="1 0 0"/>
    <limit effort="1000" lower="0" upper="0.8757" velocity="0.5"/>
    <mimic joint="gripper_finger_joint" multiplier="1" offset="0"/>
  </joint>
  <joint name="gripper_left_inner_finger_joint" type="revolute">
    <origin rpy="0 0 0" xyz="0 0.0061 0.0471"/>
    <parent link="gripper_left_outer_finger"/>
    <child link="gripper_left_inner_finger"/>
    <axis xyz="1 0 0"/>
    <limit effort="1000" lower="-0.8757" upper="0" velocity="0.5"/>
    <mimic joint="gripper_finger_joint" multiplier="-1" offset="0"/>
  </joint>
  <joint name="gripper_left_inner_finger_pad_joint" type="fixed">
    <origin rpy="0 0 0" xyz="0 -0.0220203446692936 0.03242"/>
    <parent link="gripper_left_inner_finger"/>
    <child link="gripper_left_inner_finger_pad"/>
    <axis xyz="0 0 1"/>
  </joint>
  <joint name="gripper_finger_joint" type="revolute">
    <origin rpy="0 0 3.141592653589793" xyz="0 -0.0306011 0.054904"/>
    <parent link="gripper_robotiq_arg2f_base_link"/>
    <child link="gripper_left_outer_knuckle"/>
    <axis xyz="1 0 0"/>
    <limit effort="1000" lower="0" upper="0.8" velocity="0.5"/>
  </joint>
  <joint name="gripper_right_outer_finger_joint" type="fixed">
    <origin rpy="0 0 0" xyz="0 0.0315 -0.0041"/>
    <parent link="gripper_right_outer_knuckle"/>
    <child link="gripper_right_outer_finger"/>
    <axis xyz="1 0 0"/>
  </joint>
  <joint name="gripper_right_inner_knuckle_joint" type="revolute">
    <!-- <origin xyz="0 ${reflect * -0.0127} 0.06142" rpy="${pi / 2 + .725} 0 ${(reflect - 1) * pi / 2}" /> -->
    <origin rpy="0 0 0.0" xyz="0 0.0127 0.06142"/>
    <parent link="gripper_robotiq_arg2f_base_link"/>
    <child link="gripper_right_inner_knuckle"/>
    <axis xyz="1 0 0"/>
    <limit effort="1000" lower="0" upper="0.8757" velocity="0.5"/>
    <mimic joint="gripper_finger_joint" multiplier="1" offset="0"/>
  </joint>
  <joint name="gripper_right_inner_finger_joint" type="revolute">
    <origin rpy="0 0 0" xyz="0 0.0061 0.0471"/>
    <parent link="gripper_right_outer_finger"/>
    <child link="gripper_right_inner_finger"/>
    <axis xyz="1 0 0"/>
    <limit effort="1000" lower="-0.8757" upper="0" velocity="0.5"/>
    <mimic joint="gripper_finger_joint" multiplier="-1" offset="0"/>
  </joint>
  <joint name="gripper_right_inner_finger_pad_joint" type="fixed">
    <origin rpy="0 0 0" xyz="0 -0.0220203446692936 0.03242"/>
    <parent link="gripper_right_inner_finger"/>
    <child link="gripper_right_inner_finger_pad"/>
    <axis xyz="0 0 1"/>
  </joint>
  <link name="gripper_right_outer_knuckle">
    <inertial>
      <origin rpy="0 0 0" xyz="-0.000200000000003065 0.0199435877845359 0.0292245259211331"/>
      <mass value="0.00853198276973456"/>
      <inertia ixx="2.89328108496468E-06" ixy="-1.57935047237397E-19" ixz="-1.93980378593255E-19" iyy="1.86719750325683E-06" iyz="-1.21858577871576E-06" izz="1.21905238907251E-06"/>
    </inertial>
    <visual>
      <origin rpy="0 0 0" xyz="0 0 0"/>
      <geometry>
        <mesh filename="package://robotiq_2f_85_gripper_visualization/meshes/visual/robotiq_arg2f_85_outer_knuckle.dae" scale="0.001 0.001 0.001"/>
      </geometry>
      <material name="">
        <color rgba="0.792156862745098 0.819607843137255 0.933333333333333 1"/>
      </material>
    </visual>
    <collision>
      <origin rpy="0 0 0" xyz="0 0 0"/>
      <geometry>
        <mesh filename="package://robotiq_2f_85_gripper_visualization/meshes/collision/robotiq_arg2f_85_outer_knuckle.dae" scale="0.001 0.001 0.001"/>
      </geometry>
    </collision>
  </link>
  <link name="gripper_right_outer_finger">
    <inertial>
      <origin rpy="0 0 0" xyz="0.00030115855001899 0.0373907951953854 -0.0208027427000385"/>
      <mass value="0.022614240507152"/>
      <inertia ixx="1.52518312458174E-05" ixy="9.76583423954399E-10" ixz="-5.43838577022588E-10" iyy="6.17694243867776E-06" iyz="6.78636130740228E-06" izz="1.16494917907219E-05"/>
    </inertial>
    <visual>
      <origin rpy="0 0 0" xyz="0 0 0"/>
      <geometry>
        <mesh filename="package://robotiq_2f_85_gripper_visualization/meshes/visual/robotiq_arg2f_85_outer_finger.dae" scale="0.001 0.001 0.001"/>
      </geometry>
      <material name="">
        <color rgba="0.1 0.1 0.1 1"/>
      </material>
    </visual>
    <collision>
      <origin rpy="0 0 0" xyz="0 0 0"/>
      <geometry>
        <mesh filename="package://robotiq_2f_85_gripper_visualization/meshes/collision/robotiq_arg2f_85_outer_finger.dae" scale="0.001 0.001 0.001"/>
      </geometry>
    </collision>
  </link>
  <link name="gripper_right_inner_finger">
    <inertial>
      <origin rpy="0 0 0" xyz="0.000299999999999317 0.0160078233491243 -0.0136945669206257"/>
      <mass value="0.0104003125914103"/>
      <inertia ixx="2.71909453810972E-06" ixy="1.35402465472579E-21" ixz="-7.1817349065269E-22" iyy="7.69100314106116E-07" iyz="6.74715432769696E-07" izz="2.30315190420171E-06"/>
    </inertial>
    <visual>
      <origin rpy="0 0 0" xyz="0 0 0"/>
      <geometry>
        <mesh filename="package://robotiq_2f_85_gripper_visualization/meshes/visual/robotiq_arg2f_85_inner_finger.dae" scale="0.001 0.001 0.001"/>
      </geometry>
      <material name="">
        <color rgba="0.1 0.1 0.1 1"/>
      </material>
    </visual>
    <collision>
      <origin rpy="0 0 0" xyz="0 0 0"/>
      <geometry>
        <mesh filename="package://robotiq_2f_85_gripper_visualization/meshes/collision/robotiq_arg2f_85_inner_finger.dae" scale="0.001 0.001 0.001"/>
      </geometry>
    </collision>
  </link>
  <link name="gripper_right_inner_finger_pad">
    <visual>
      <origin rpy="0 0 0" xyz="0 0 0"/>
      <geometry>
        <box size="0.022 0.00635 0.0375"/>
      </geometry>
      <material name="">
        <color rgba="0.9 0.9 0.9 1"/>
      </material>
    </visual>
    <collision>
      <origin rpy="0 0 0" xyz="0 0 0"/>
      <geometry>
        <box size="0.022 0.00635 0.0375"/>
      </geometry>
      <material name="">
        <color rgba="0.9 0.0 0.0 1"/>
      </material>
    </collision>
  </link>
  <link name="gripper_right_inner_knuckle">
    <inertial>
      <origin rpy="0 0 0" xyz="0.000123011831763771 0.0507850843201817 0.00103968640075166"/>
      <mass value="0.0271177346495152"/>
      <inertia ixx="2.61910379223783E-05" ixy="-2.43616858946494E-07" ixz="-6.37789906117123E-09" iyy="2.8270243746167E-06" iyz="-5.37200748039765E-07" izz="2.83695868220296E-05"/>
    </inertial>
    <visual>
      <origin rpy="0 0 0" xyz="0 0 0"/>
      <geometry>
        <mesh filename="package://robotiq_2f_85_gripper_visualization/meshes/visual/robotiq_arg2f_85_inner_knuckle.dae" scale="0.001 0.001 0.001"/>
      </geometry>
      <material name="">
        <color rgba="0.1 0.1 0.1 1"/>
      </material>
    </visual>
    <collision>
      <origin rpy="0 0 0" xyz="0 0 0"/>
      <geometry>
        <mesh filename="package://robotiq_2f_85_gripper_visualization/meshes/collision/robotiq_arg2f_85_inner_knuckle.dae" scale="0.001 0.001 0.001"/>
      </geometry>
    </collision>
  </link>
  <joint name="gripper_right_finger_joint" type="revolute">
    <origin rpy="0 0 0" xyz="0 0.0306011 0.054904"/>
    <parent link="gripper_robotiq_arg2f_base_link"/>
    <child link="gripper_right_outer_knuckle"/>
    <axis xyz="1 0 0"/>
    <limit effort="1000" lower="0" upper="0.81" velocity="0.5"/>
    <mimic joint="gripper_finger_joint" multiplier="1" offset="0"/>
  </joint>
  <link name="base_link"/>
  <joint name="base_joint" type="fixed">
    <origin rpy="0 0 0" xyz="0 0 0.15"/>
    <parent link="base_link"/>
    <child link="stand"/>
  </joint>
  <joint name="robot_plate_arm_base_link_joint" type="fixed">
    <parent link="robot_plate"/>
    <child link="arm_base_link"/>
    <origin rpy="0 3.141592653589793 4.71238898038469" xyz="0 0.00175 -0.00885"/>
  </joint>
  <link name="coupling">
    <visual>
      <origin rpy="0 0 3.141592653589793" xyz="0 0 0"/>
      <geometry>
        <mesh filename="package://tahoma_description/meshes/robotiq_gripper_coupling.stl"/>
      </geometry>
      <material name="">
        <color rgba="0.1 0.1 0.1 1"/>
      </material>
    </visual>
    <collision>
      <geometry>
        <cylinder length=".0139" radius=".0375"/>
      </geometry>
    </collision>
  </link>
  <joint name="coupling_link_gripper_robotiq_arg2f_base_link_joint" type="fixed">
    <origin rpy="0 0 1.5707963267948966" xyz="0 0 0.012"/>
    <parent link="coupling"/>
    <child link="gripper_base_link"/>
  </joint>
  <joint name="arm_tool0-coupling_joint" type="fixed">
    <parent link="arm_tool0"/>
    <child link="coupling"/>
  </joint>
  <link name="camera_lower_right_mount"/>
  <joint name="camera_beam_lower_camera_lower_right_mount_joint" type="fixed">
    <parent link="camera_beam_lower"/>
    <child link="camera_lower_right_mount"/>
    <origin rpy="-1.5707963267948966 0 0.1767088560700366" xyz="-0.00 -0.2715 0.09"/>
  </joint>
  <link name="camera_lower_left_mount"/>
  <joint name="camera_beam_lower_camera_lower_left_mount_joint" type="fixed">
    <parent link="camera_beam_lower"/>
    <child link="camera_lower_left_mount"/>
    <!-- Link is centered on the optical frames. Slight offset in Y direction to compensate -->
    <origin rpy="-1.5707963267948966 0 -0.1767088560700366" xyz="-0.00 0.2285 0.09"/>
  </joint>
  <!-- camera body, with origin at bottom screw mount -->
  <joint name="camera_lower_right_joint" type="fixed">
    <origin rpy="0 0 0" xyz="0 0 0"/>
    <parent link="camera_lower_right_mount"/>
    <child link="camera_lower_right_bottom_screw_frame"/>
  </joint>
  <link name="camera_lower_right_bottom_screw_frame"/>
  <joint name="camera_lower_right_link_joint" type="fixed">
    <origin rpy="0 0 0" xyz="0.007500000000000001 0.0 0.021150000000000002"/>
    <parent link="camera_lower_right_bottom_screw_frame"/>
    <child link="camera_lower_right_link"/>
  </joint>
  <link name="camera_lower_right_link">
    <visual>
      <origin rpy="1.5707963267948966 0 1.5707963267948966" xyz="0.0045 0 0.009000000000000001"/>
      <geometry>
        <mesh filename="package://realsense2_description/meshes/l515.dae"/>
      </geometry>
    </visual>
    <collision>
      <origin rpy="1.5707963267948966 0 1.5707963267948966" xyz="-0.0085 0 0.009000000000000001"/>
      <geometry>
        <cylinder length="0.026" radius="0.0305"/>
      </geometry>
    </collision>
    <inertial>
      <!-- The following are not reliable values, and should not be used for modeling -->
      <!-- calculated assuming full cylinder as described here: https://en.wikipedia.org/wiki/List_of_moments_of_inertia -->
      <mass value="0.095"/>
      <origin xyz="0 0 0"/>
      <inertia ixx="0.000044" ixy="0.0" ixz="0.0" iyy="0.000027" iyz="0.0" izz="0.000027"/>
    </inertial>
  </link>
  <joint name="camera_lower_right_lower_mount_joint" type="fixed">
    <origin rpy="0 0 0" xyz="-0.013999999999999999 0 0.01015"/>
    <parent link="camera_lower_right_bottom_screw_frame"/>
    <child link="camera_lower_right_lower_mount"/>
  </joint>
  <link name="camera_lower_right_lower_mount"/>
  <joint name="camera_lower_right_upper_mount_joint" type="fixed">
    <origin rpy="0 0 0" xyz="-0.013999999999999999 0 0.05015"/>
    <parent link="camera_lower_right_bottom_screw_frame"/>
    <child link="camera_lower_right_upper_mount"/>
  </joint>
  <link name="camera_lower_right_upper_mount"/>
  <!-- camera depth joints and links -->
  <joint name="camera_lower_right_depth_joint" type="fixed">
    <origin rpy="0 0 0" xyz="0 0 0"/>
    <parent link="camera_lower_right_link"/>
    <child link="camera_lower_right_depth_frame"/>
  </joint>
  <link name="camera_lower_right_depth_frame"/>
  <joint name="camera_lower_right_depth_optical_joint" type="fixed">
    <origin rpy="-1.5707963267948966 0 -1.5707963267948966" xyz="0 0 0"/>
    <parent link="camera_lower_right_depth_frame"/>
    <child link="camera_lower_right_depth_optical_frame"/>
  </joint>
  <link name="camera_lower_right_depth_optical_frame"/>
  <!-- camera left IR joints and links -->
  <joint name="camera_lower_right_infra_joint" type="fixed">
    <origin rpy="0 0 0" xyz="0 0.0 0"/>
    <parent link="camera_lower_right_link"/>
    <child link="camera_lower_right_infra_frame"/>
  </joint>
  <link name="camera_lower_right_infra_frame"/>
  <joint name="camera_lower_right_infra_optical_joint" type="fixed">
    <origin rpy="-1.5707963267948966 0 -1.5707963267948966" xyz="0 0 0"/>
    <parent link="camera_lower_right_infra_frame"/>
    <child link="camera_lower_right_infra_optical_frame"/>
  </joint>
  <link name="camera_lower_right_infra_optical_frame"/>
  <!-- camera color joints and links -->
  <joint name="camera_lower_right_color_joint" type="fixed">
    <origin rpy="0 0 0" xyz="0 0 0.024"/>
    <parent link="camera_lower_right_link"/>
    <child link="camera_lower_right_color_frame"/>
  </joint>
  <link name="camera_lower_right_color_frame"/>
  <joint name="camera_lower_right_color_optical_joint" type="fixed">
    <origin rpy="-1.5707963267948966 0 -1.5707963267948966" xyz="0 0 0"/>
    <parent link="camera_lower_right_color_frame"/>
    <child link="camera_lower_right_color_optical_frame"/>
  </joint>
  <link name="camera_lower_right_color_optical_frame"/>
  <!-- camera IMU joints and links -->
  <link name="camera_lower_right_gyro_frame"/>
  <link name="camera_lower_right_gyro_optical_frame"/>
  <link name="camera_lower_right_accel_frame"/>
  <link name="camera_lower_right_accel_optical_frame"/>
  <joint name="camera_lower_right_gyro_joint" type="fixed">
    <origin rpy="-0.006161012 0.020193459 0.016301375" xyz="-0.00410137791186571 -0.0129784867167473 0.00256138201802969"/>
    <parent link="camera_lower_right_color_frame"/>
    <child link="camera_lower_right_gyro_frame"/>
  </joint>
  <joint name="camera_lower_right_gyro_optical_joint" type="fixed">
    <origin rpy="-1.5707963267948966 0 -1.5707963267948966" xyz="0 0 0"/>
    <parent link="camera_lower_right_gyro_frame"/>
    <child link="camera_lower_right_gyro_optical_frame"/>
  </joint>
  <joint name="camera_lower_right_accel_joint" type="fixed">
    <origin rpy="-0.006161012 0.020193459 0.016301375" xyz="-0.00410137791186571 -0.0129784867167473 0.00256138201802969"/>
    <parent link="camera_lower_right_color_frame"/>
    <child link="camera_lower_right_accel_frame"/>
  </joint>
  <joint name="camera_lower_right_accel_optical_joint" type="fixed">
    <origin rpy="-1.5707963267948966 0 -1.5707963267948966" xyz="0 0 0"/>
    <parent link="camera_lower_right_accel_frame"/>
    <child link="camera_lower_right_accel_optical_frame"/>
  </joint>
  <!-- camera body, with origin at bottom screw mount -->
  <joint name="camera_lower_left_joint" type="fixed">
    <origin rpy="0 0 0" xyz="0 0 0"/>
    <parent link="camera_lower_left_mount"/>
    <child link="camera_lower_left_bottom_screw_frame"/>
  </joint>
  <link name="camera_lower_left_bottom_screw_frame"/>
  <joint name="camera_lower_left_link_joint" type="fixed">
    <origin rpy="0 0 0" xyz="0.007500000000000001 0.0 0.021150000000000002"/>
    <parent link="camera_lower_left_bottom_screw_frame"/>
    <child link="camera_lower_left_link"/>
  </joint>
  <link name="camera_lower_left_link">
    <visual>
      <origin rpy="1.5707963267948966 0 1.5707963267948966" xyz="0.0045 0 0.009000000000000001"/>
      <geometry>
        <mesh filename="package://realsense2_description/meshes/l515.dae"/>
      </geometry>
    </visual>
    <collision>
      <origin rpy="1.5707963267948966 0 1.5707963267948966" xyz="-0.0085 0 0.009000000000000001"/>
      <geometry>
        <cylinder length="0.026" radius="0.0305"/>
      </geometry>
    </collision>
    <inertial>
      <!-- The following are not reliable values, and should not be used for modeling -->
      <!-- calculated assuming full cylinder as described here: https://en.wikipedia.org/wiki/List_of_moments_of_inertia -->
      <mass value="0.095"/>
      <origin xyz="0 0 0"/>
      <inertia ixx="0.000044" ixy="0.0" ixz="0.0" iyy="0.000027" iyz="0.0" izz="0.000027"/>
    </inertial>
  </link>
  <joint name="camera_lower_left_lower_mount_joint" type="fixed">
    <origin rpy="0 0 0" xyz="-0.013999999999999999 0 0.01015"/>
    <parent link="camera_lower_left_bottom_screw_frame"/>
    <child link="camera_lower_left_lower_mount"/>
  </joint>
  <link name="camera_lower_left_lower_mount"/>
  <joint name="camera_lower_left_upper_mount_joint" type="fixed">
    <origin rpy="0 0 0" xyz="-0.013999999999999999 0 0.05015"/>
    <parent link="camera_lower_left_bottom_screw_frame"/>
    <child link="camera_lower_left_upper_mount"/>
  </joint>
  <link name="camera_lower_left_upper_mount"/>
  <!-- camera depth joints and links -->
  <joint name="camera_lower_left_depth_joint" type="fixed">
    <origin rpy="0 0 0" xyz="0 0 0"/>
    <parent link="camera_lower_left_link"/>
    <child link="camera_lower_left_depth_frame"/>
  </joint>
  <link name="camera_lower_left_depth_frame"/>
  <joint name="camera_lower_left_depth_optical_joint" type="fixed">
    <origin rpy="-1.5707963267948966 0 -1.5707963267948966" xyz="0 0 0"/>
    <parent link="camera_lower_left_depth_frame"/>
    <child link="camera_lower_left_depth_optical_frame"/>
  </joint>
  <link name="camera_lower_left_depth_optical_frame"/>
  <!-- camera left IR joints and links -->
  <joint name="camera_lower_left_infra_joint" type="fixed">
    <origin rpy="0 0 0" xyz="0 0.0 0"/>
    <parent link="camera_lower_left_link"/>
    <child link="camera_lower_left_infra_frame"/>
  </joint>
  <link name="camera_lower_left_infra_frame"/>
  <joint name="camera_lower_left_infra_optical_joint" type="fixed">
    <origin rpy="-1.5707963267948966 0 -1.5707963267948966" xyz="0 0 0"/>
    <parent link="camera_lower_left_infra_frame"/>
    <child link="camera_lower_left_infra_optical_frame"/>
  </joint>
  <link name="camera_lower_left_infra_optical_frame"/>
  <!-- camera color joints and links -->
  <joint name="camera_lower_left_color_joint" type="fixed">
    <origin rpy="0 0 0" xyz="0 0 0.024"/>
    <parent link="camera_lower_left_link"/>
    <child link="camera_lower_left_color_frame"/>
  </joint>
  <link name="camera_lower_left_color_frame"/>
  <joint name="camera_lower_left_color_optical_joint" type="fixed">
    <origin rpy="-1.5707963267948966 0 -1.5707963267948966" xyz="0 0 0"/>
    <parent link="camera_lower_left_color_frame"/>
    <child link="camera_lower_left_color_optical_frame"/>
  </joint>
  <link name="camera_lower_left_color_optical_frame"/>
  <!-- camera IMU joints and links -->
  <link name="camera_lower_left_gyro_frame"/>
  <link name="camera_lower_left_gyro_optical_frame"/>
  <link name="camera_lower_left_accel_frame"/>
  <link name="camera_lower_left_accel_optical_frame"/>
  <joint name="camera_lower_left_gyro_joint" type="fixed">
    <origin rpy="-0.006161012 0.020193459 0.016301375" xyz="-0.00410137791186571 -0.0129784867167473 0.00256138201802969"/>
    <parent link="camera_lower_left_color_frame"/>
    <child link="camera_lower_left_gyro_frame"/>
  </joint>
  <joint name="camera_lower_left_gyro_optical_joint" type="fixed">
    <origin rpy="-1.5707963267948966 0 -1.5707963267948966" xyz="0 0 0"/>
    <parent link="camera_lower_left_gyro_frame"/>
    <child link="camera_lower_left_gyro_optical_frame"/>
  </joint>
  <joint name="camera_lower_left_accel_joint" type="fixed">
    <origin rpy="-0.006161012 0.020193459 0.016301375" xyz="-0.00410137791186571 -0.0129784867167473 0.00256138201802969"/>
    <parent link="camera_lower_left_color_frame"/>
    <child link="camera_lower_left_accel_frame"/>
  </joint>
  <joint name="camera_lower_left_accel_optical_joint" type="fixed">
    <origin rpy="-1.5707963267948966 0 -1.5707963267948966" xyz="0 0 0"/>
    <parent link="camera_lower_left_accel_frame"/>
    <child link="camera_lower_left_accel_optical_frame"/>
  </joint>
</robot>
